Workbook

Sheet Ассортимент
A1: TMFF — стартовый ассортимент
A2: Синим — данные AliExpress (варианты лотов собраны в Chrome 25.09.2026, конструкторы — из поиска aliexpress.com), чёрным — формулы, жёлтым — проверить. Цена — за товар, без платной доставки, если она есть. У конструкторов с aliexpress.com жёлтая цена — верхняя оценка: реальная может быть до двух раз ниже.
A3: Повторы убраны: болид + пилот + ливрея + масштаб встречаются один раз, по самой низкой цене. Другие лоты с тем же вариантом — в «Запасной лот». «Вариант на Ali» — что выбрать при заказе.
A4: Раздел | B4: Название на сайте | C4: Масштаб | D4: Цена на Ali, ₽ | E4: Наша цена, ₽ | F4: Прибыль с шт., ₽ | G4: Болид | H4: Пилот | I4: Ливрея / версия | J4: Год | K4: Заказов лота | L4: Рейтинг | M4: Лот | N4: Вариант на Ali | O4: Запасной лот · цена | P4: Повтор? | Q4: Лимит 1:24 | R4: Заметки и что проверить
A5: Модели 1:43 — сезон 2025 | B5: Red Bull RB21 — Цунода #22 | C5: 1:43 | D5: 789 | E5: =IF(D5="","",IF(D5<Параметры!$B$4,CEILING(D5*Параметры!$B$5,100)-10,IF(D5<=Параметры!$B$6,CEILING(D5*Параметры!$B$7,100)-10,CEILING(D5*Параметры!$B$8,100)-10))) -> 1590 | F5: =IF(D5="","",ROUND(E5*(1-Параметры!$B$9-Параметры!$B$10-Параметры!$B$11)-D5,0)) -> 570 | G5: Red Bull RB21 | H5: Цунода #22 | I5: стандартная | J5: 2025 | K5: 1947 | L5: 4.9 | M5: открыть | N5: 22-TSU-Bahrain | O5: 755468 · 879 ₽ | P5: =IF(COUNTIFS($G$5:$G$66,G5,$H$5:$H$66,H5,$I$5:$I$66,I5,$C$5:$C$66,C5)>1,"повтор","") | Q5: =IF(C5<>"1:24","",IF(D5="","проверить",IF(D5<=Параметры!$B$12,"ок","дороже лимита")))
A6: Модели 1:43 — сезон 2025 | B6: Red Bull RB21 — Цунода #22, белая, ГП Японии | C6: 1:43 | D6: 789 | E6: =IF(D6="","",IF(D6<Параметры!$B$4,CEILING(D6*Параметры!$B$5,100)-10,IF(D6<=Параметры!$B$6,CEILING(D6*Параметры!$B$7,100)-10,CEILING(D6*Параметры!$B$8,100)-10))) -> 1590 | F6: =IF(D6="","",ROUND(E6*(1-Параметры!$B$9-Параметры!$B$10-Параметры!$B$11)-D6,0)) -> 570 | G6: Red Bull RB21 | H6: Цунода #22 | I6: белая, ГП Японии | J6: 2025 | K6: 1947 | L6: 4.9 | M6: открыть | N6: 22-TSU-Japan | O6: 755468 · 879 ₽ | P6: =IF(COUNTIFS($G$5:$G$66,G6,$H$5:$H$66,H6,$I$5:$I$66,I6,$C$5:$C$66,C6)>1,"повтор","") | Q6: =IF(C6<>"1:24","",IF(D6="","проверить",IF(D6<=Параметры!$B$12,"ок","дороже лимита"))) | R6: Белая ливрея в честь Honda (Сузука 2025). Обязательно в ассортименте.
A7: Модели 1:43 — сезон 2025 | B7: Red Bull RB21 — Ферстаппен #1 | C7: 1:43 | D7: 879 | E7: =IF(D7="","",IF(D7<Параметры!$B$4,CEILING(D7*Параметры!$B$5,100)-10,IF(D7<=Параметры!$B$6,CEILING(D7*Параметры!$B$7,100)-10,CEILING(D7*Параметры!$B$8,100)-10))) -> 1790 | F7: =IF(D7="","",ROUND(E7*(1-Параметры!$B$9-Параметры!$B$10-Параметры!$B$11)-D7,0)) -> 651 | G7: Red Bull RB21 | H7: Ферстаппен #1 | I7: стандартная | J7: 2025 | K7: 791 | L7: 4.9 | M7: открыть | N7: 2025 RB21-1BHR | P7: =IF(COUNTIFS($G$5:$G$66,G7,$H$5:$H$66,H7,$I$5:$I$66,I7,$C$5:$C$66,C7)>1,"повтор","") | Q7: =IF(C7<>"1:24","",IF(D7="","проверить",IF(D7<=Параметры!$B$12,"ок","дороже лимита")))
A8: Модели 1:43 — сезон 2025 | B8: Red Bull RB21 — Ферстаппен #1, белая, ГП Японии | C8: 1:43 | D8: 789 | E8: =IF(D8="","",IF(D8<Параметры!$B$4,CEILING(D8*Параметры!$B$5,100)-10,IF(D8<=Параметры!$B$6,CEILING(D8*Параметры!$B$7,100)-10,CEILING(D8*Параметры!$B$8,100)-10))) -> 1590 | F8: =IF(D8="","",ROUND(E8*(1-Параметры!$B$9-Параметры!$B$10-Параметры!$B$11)-D8,0)) -> 570 | G8: Red Bull RB21 | H8: Ферстаппен #1 | I8: белая, ГП Японии | J8: 2025 | K8: 1947 | L8: 4.9 | M8: открыть | N8: 1-VER-Japan | O8: 755468 · 879 ₽ | P8: =IF(COUNTIFS($G$5:$G$66,G8,$H$5:$H$66,H8,$I$5:$I$66,I8,$C$5:$C$66,C8)>1,"повтор","") | Q8: =IF(C8<>"1:24","",IF(D8="","проверить",IF(D8<=Параметры!$B$12,"ок","дороже лимита"))) | R8: Белая ливрея в честь Honda (Сузука 2025). Обязательно в ассортименте.
A9: Модели 1:43 — сезон 2025 | B9: Ferrari SF-25 — Хэмилтон #44 | C9: 1:43 | D9: 879 | E9: =IF(D9="","",IF(D9<Параметры!$B$4,CEILING(D9*Параметры!$B$5,100)-10,IF(D9<=Параметры!$B$6,CEILING(D9*Параметры!$B$7,100)-10,CEILING(D9*Параметры!$B$8,100)-10))) -> 1790 | F9: =IF(D9="","",ROUND(E9*(1-Параметры!$B$9-Параметры!$B$10-Параметры!$B$11)-D9,0)) -> 651 | G9: Ferrari SF-25 | H9: Хэмилтон #44 | I9: стандартная | J9: 2025 | K9: 791 | L9: 4.9 | M9: открыть | N9: 2025 SF25-44 | P9: =IF(COUNTIFS($G$5:$G$66,G9,$H$5:$H$66,H9,$I$5:$I$66,I9,$C$5:$C$66,C9)>1,"повтор","") | Q9: =IF(C9<>"1:24","",IF(D9="","проверить",IF(D9<=Параметры!$B$12,"ок","дороже лимита")))
A10: Модели 1:43 — сезон 2025 | B10: Ferrari SF-25 — Хэмилтон #44, ГП Майами | C10: 1:43 | D10: 789 | E10: =IF(D10="","",IF(D10<Параметры!$B$4,CEILING(D10*Параметры!$B$5,100)-10,IF(D10<=Параметры!$B$6,CEILING(D10*Параметры!$B$7,100)-10,CEILING(D10*Параметры!$B$8,100)-10))) -> 1590 | F10: =IF(D10="","",ROUND(E10*(1-Параметры!$B$9-Параметры!$B$10-Параметры!$B$11)-D10,0)) -> 570 | G10: Ferrari SF-25 | H10: Хэмилтон #44 | I10: ГП Майами | J10: 2025 | K10: 1947 | L10: 4.9 | M10: открыть | N10: 44-HAM-Miami | P10: =IF(COUNTIFS($G$5:$G$66,G10,$H$5:$H$66,H10,$I$5:$I$66,I10,$C$5:$C$66,C10)>1,"повтор","") | Q10: =IF(C10<>"1:24","",IF(D10="","проверить",IF(D10<=Параметры!$B$12,"ок","дороже лимита"))) | R10: Спецливрея Ferrari на Гран-при Майами.
A11: Модели 1:43 — сезон 2025 | B11: Ferrari SF-25 — Леклер #16 | C11: 1:43 | D11: 789 | E11: =IF(D11="","",IF(D11<Параметры!$B$4,CEILING(D11*Параметры!$B$5,100)-10,IF(D11<=Параметры!$B$6,CEILING(D11*Параметры!$B$7,100)-10,CEILING(D11*Параметры!$B$8,100)-10))) -> 1590 | F11: =IF(D11="","",ROUND(E11*(1-Параметры!$B$9-Параметры!$B$10-Параметры!$B$11)-D11,0)) -> 570 | G11: Ferrari SF-25 | H11: Леклер #16 | I11: стандартная | J11: 2025 | K11: 1947 | L11: 4.9 | M11: открыть | N11: 16-LEC | O11: 755468 · 879 ₽ | P11: =IF(COUNTIFS($G$5:$G$66,G11,$H$5:$H$66,H11,$I$5:$I$66,I11,$C$5:$C$66,C11)>1,"повтор","") | Q11: =IF(C11<>"1:24","",IF(D11="","проверить",IF(D11<=Параметры!$B$12,"ок","дороже лимита")))
A12: Модели 1:43 — сезон 2025 | B12: Ferrari SF-25 — Леклер #16, ГП Майами | C12: 1:43 | D12: 789 | E12: =IF(D12="","",IF(D12<Параметры!$B$4,CEILING(D12*Параметры!$B$5,100)-10,IF(D12<=Параметры!$B$6,CEILING(D12*Параметры!$B$7,100)-10,CEILING(D12*Параметры!$B$8,100)-10))) -> 1590 | F12: =IF(D12="","",ROUND(E12*(1-Параметры!$B$9-Параметры!$B$10-Параметры!$B$11)-D12,0)) -> 570 | G12: Ferrari SF-25 | H12: Леклер #16 | I12: ГП Майами | J12: 2025 | K12: 1947 | L12: 4.9 | M12: открыть | N12: 16-LEC-Miami | O12: 755468 · 879 ₽ | P12: =IF(COUNTIFS($G$5:$G$66,G12,$H$5:$H$66,H12,$I$5:$I$66,I12,$C$5:$C$66,C12)>1,"повтор","") | Q12: =IF(C12<>"1:24","",IF(D12="","проверить",IF(D12<=Параметры!$B$12,"ок","дороже лимита"))) | R12: Спецливрея Ferrari на Гран-при Майами.
A13: Модели 1:43 — сезон 2025 | B13: Mercedes W16 — Антонелли #12 | C13: 1:43 | D13: 879 | E13: =IF(D13="","",IF(D13<Параметры!$B$4,CEILING(D13*Параметры!$B$5,100)-10,IF(D13<=Параметры!$B$6,CEILING(D13*Параметры!$B$7,100)-10,CEILING(D13*Параметры!$B$8,100)-10))) -> 1790 | F13: =IF(D13="","",ROUND(E13*(1-Параметры!$B$9-Параметры!$B$10-Параметры!$B$11)-D13,0)) -> 651 | G13: Mercedes W16 | H13: Антонелли #12 | I13: стандартная | J13: 2025 | K13: 791 | L13: 4.9 | M13: открыть | N13: 2025 W16 E-12 | P13: =IF(COUNTIFS($G$5:$G$66,G13,$H$5:$H$66,H13,$I$5:$I$66,I13,$C$5:$C$66,C13)>1,"повтор","") | Q13: =IF(C13<>"1:24","",IF(D13="","проверить",IF(D13<=Параметры!$B$12,"ок","дороже лимита")))
A14: Модели 1:43 — сезон 2025 | B14: Mercedes W16 — Рассел #63 | C14: 1:43 | D14: 879 | E14: =IF(D14="","",IF(D14<Параметры!$B$4,CEILING(D14*Параметры!$B$5,100)-10,IF(D14<=Параметры!$B$6,CEILING(D14*Параметры!$B$7,100)-10,CEILING(D14*Параметры!$B$8,100)-10))) -> 1790 | F14: =IF(D14="","",ROUND(E14*(1-Параметры!$B$9-Параметры!$B$10-Параметры!$B$11)-D14,0)) -> 651 | G14: Mercedes W16 | H14: Рассел #63 | I14: стандартная | J14: 2025 | K14: 791 | L14: 4.9 | M14: открыть | N14: 2025 W16 E-63 | P14: =IF(COUNTIFS($G$5:$G$66,G14,$H$5:$H$66,H14,$I$5:$I$66,I14,$C$5:$C$66,C14)>1,"повтор","") | Q14: =IF(C14<>"1:24","",IF(D14="","проверить",IF(D14<=Параметры!$B$12,"ок","дороже лимита")))
A15: Модели 1:43 — сезон 2025 | B15: McLaren MCL39 — Норрис #4 | C15: 1:43 | D15: 879 | E15: =IF(D15="","",IF(D15<Параметры!$B$4,CEILING(D15*Параметры!$B$5,100)-10,IF(D15<=Параметры!$B$6,CEILING(D15*Параметры!$B$7,100)-10,CEILING(D15*Параметры!$B$8,100)-10))) -> 1790 | F15: =IF(D15="","",ROUND(E15*(1-Параметры!$B$9-Параметры!$B$10-Параметры!$B$11)-D15,0)) -> 651 | G15: McLaren MCL39 | H15: Норрис #4 | I15: стандартная | J15: 2025 | K15: 791 | L15: 4.9 | M15: открыть | N15: 2025 MCL39-4 | P15: =IF(COUNTIFS($G$5:$G$66,G15,$H$5:$H$66,H15,$I$5:$I$66,I15,$C$5:$C$66,C15)>1,"повтор","") | Q15: =IF(C15<>"1:24","",IF(D15="","проверить",IF(D15<=Параметры!$B$12,"ок","дороже лимита")))
A16: Модели 1:43 — сезон 2025 | B16: McLaren MCL39 — Пиастри #81 | C16: 1:43 | D16: 879 | E16: =IF(D16="","",IF(D16<Параметры!$B$4,CEILING(D16*Параметры!$B$5,100)-10,IF(D16<=Параметры!$B$6,CEILING(D16*Параметры!$B$7,100)-10,CEILING(D16*Параметры!$B$8,100)-10))) -> 1790 | F16: =IF(D16="","",ROUND(E16*(1-Параметры!$B$9-Параметры!$B$10-Параметры!$B$11)-D16,0)) -> 651 | G16: McLaren MCL39 | H16: Пиастри #81 | I16: стандартная | J16: 2025 | K16: 791 | L16: 4.9 | M16: открыть | N16: 2025 MCL39-81 | P16: =IF(COUNTIFS($G$5:$G$66,G16,$H$5:$H$66,H16,$I$5:$I$66,I16,$C$5:$C$66,C16)>1,"повтор","") | Q16: =IF(C16<>"1:24","",IF(D16="","проверить",IF(D16<=Параметры!$B$12,"ок","дороже лимита")))
A17: Модели 1:43 — сезон 2025 | B17: Aston Martin AMR25 — Алонсо #14 | C17: 1:43 | D17: 879 | E17: =IF(D17="","",IF(D17<Параметры!$B$4,CEILING(D17*Параметры!$B$5,100)-10,IF(D17<=Параметры!$B$6,CEILING(D17*Параметры!$B$7,100)-10,CEILING(D17*Параметры!$B$8,100)-10))) -> 1790 | F17: =IF(D17="","",ROUND(E17*(1-Параметры!$B$9-Параметры!$B$10-Параметры!$B$11)-D17,0)) -> 651 | G17: Aston Martin AMR25 | H17: Алонсо #14 | I17: стандартная | J17: 2025 | K17: 791 | L17: 4.9 | M17: открыть | N17: 2025 AMR25-14 | P17: =IF(COUNTIFS($G$5:$G$66,G17,$H$5:$H$66,H17,$I$5:$I$66,I17,$C$5:$C$66,C17)>1,"повтор","") | Q17: =IF(C17<>"1:24","",IF(D17="","проверить",IF(D17<=Параметры!$B$12,"ок","дороже лимита")))
A18: Модели 1:43 — сезон 2025 | B18: Aston Martin AMR25 — Стролл #18 | C18: 1:43 | D18: 879 | E18: =IF(D18="","",IF(D18<Параметры!$B$4,CEILING(D18*Параметры!$B$5,100)-10,IF(D18<=Параметры!$B$6,CEILING(D18*Параметры!$B$7,100)-10,CEILING(D18*Параметры!$B$8,100)-10))) -> 1790 | F18: =IF(D18="","",ROUND(E18*(1-Параметры!$B$9-Параметры!$B$10-Параметры!$B$11)-D18,0)) -> 651 | G18: Aston Martin AMR25 | H18: Стролл #18 | I18: стандартная | J18: 2025 | K18: 791 | L18: 4.9 | M18: открыть | N18: 2025 AMR25-18 | P18: =IF(COUNTIFS($G$5:$G$66,G18,$H$5:$H$66,H18,$I$5:$I$66,I18,$C$5:$C$66,C18)>1,"повтор","") | Q18: =IF(C18<>"1:24","",IF(D18="","проверить",IF(D18<=Параметры!$B$12,"ок","дороже лимита")))
A19: Модели 1:43 — сезон 2025 | B19: Alpine A525 — Колапинто #43, ГП Монако | C19: 1:43 | D19: 879 | E19: =IF(D19="","",IF(D19<Параметры!$B$4,CEILING(D19*Параметры!$B$5,100)-10,IF(D19<=Параметры!$B$6,CEILING(D19*Параметры!$B$7,100)-10,CEILING(D19*Параметры!$B$8,100)-10))) -> 1790 | F19: =IF(D19="","",ROUND(E19*(1-Параметры!$B$9-Параметры!$B$10-Параметры!$B$11)-D19,0)) -> 651 | G19: Alpine A525 | H19: Колапинто #43 | I19: ГП Монако | J19: 2025 | K19: 791 | L19: 4.9 | M19: открыть | N19: 2025 A525-43MC | P19: =IF(COUNTIFS($G$5:$G$66,G19,$H$5:$H$66,H19,$I$5:$I$66,I19,$C$5:$C$66,C19)>1,"повтор","") | Q19: =IF(C19<>"1:24","",IF(D19="","проверить",IF(D19<=Параметры!$B$12,"ок","дороже лимита"))) | R19: Другой версии Alpine в лотах нет.
A20: Модели 1:43 — сезон 2025 | B20: Alpine A525 — Гасли #10, ГП Монако | C20: 1:43 | D20: 879 | E20: =IF(D20="","",IF(D20<Параметры!$B$4,CEILING(D20*Параметры!$B$5,100)-10,IF(D20<=Параметры!$B$6,CEILING(D20*Параметры!$B$7,100)-10,CEILING(D20*Параметры!$B$8,100)-10))) -> 1790 | F20: =IF(D20="","",ROUND(E20*(1-Параметры!$B$9-Параметры!$B$10-Параметры!$B$11)-D20,0)) -> 651 | G20: Alpine A525 | H20: Гасли #10 | I20: ГП Монако | J20: 2025 | K20: 791 | L20: 4.9 | M20: открыть | N20: 2025 A525-10MC | P20: =IF(COUNTIFS($G$5:$G$66,G20,$H$5:$H$66,H20,$I$5:$I$66,I20,$C$5:$C$66,C20)>1,"повтор","") | Q20: =IF(C20<>"1:24","",IF(D20="","проверить",IF(D20<=Параметры!$B$12,"ок","дороже лимита"))) | R20: Другой версии Alpine в лотах нет.
A21: Модели 1:43 — новинки 2026 | B21: Ferrari SF-26 — Хэмилтон #44 · масштаб 1:43 | C21: 1:43 | D21: 1489 | E21: =IF(D21="","",IF(D21<Параметры!$B$4,CEILING(D21*Параметры!$B$5,100)-10,IF(D21<=Параметры!$B$6,CEILING(D21*Параметры!$B$7,100)-10,CEILING(D21*Параметры!$B$8,100)-10))) -> 2990 | F21: =IF(D21="","",ROUND(E21*(1-Параметры!$B$9-Параметры!$B$10-Параметры!$B$11)-D21,0)) -> 1067 | G21: Ferrari SF-26 | H21: Хэмилтон #44 | I21: стандартная | J21: 2026 | K21: 45 | M21: открыть | N21: 2026 SF26-44 | P21: =IF(COUNTIFS($G$5:$G$66,G21,$H$5:$H$66,H21,$I$5:$I$66,I21,$C$5:$C$66,C21)>1,"повтор","") | Q21: =IF(C21<>"1:24","",IF(D21="","проверить",IF(D21<=Параметры!$B$12,"ок","дороже лимита"))) | R21: Новинка 2026, оценок ещё нет. На сайте масштаб 1:43 — в названии: модель дороже сезона 2025.
A22: Модели 1:43 — новинки 2026 | B22: Ferrari SF-26 — Леклер #16 · масштаб 1:43 | C22: 1:43 | D22: 1489 | E22: =IF(D22="","",IF(D22<Параметры!$B$4,CEILING(D22*Параметры!$B$5,100)-10,IF(D22<=Параметры!$B$6,CEILING(D22*Параметры!$B$7,100)-10,CEILING(D22*Параметры!$B$8,100)-10))) -> 2990 | F22: =IF(D22="","",ROUND(E22*(1-Параметры!$B$9-Параметры!$B$10-Параметры!$B$11)-D22,0)) -> 1067 | G22: Ferrari SF-26 | H22: Леклер #16 | I22: стандартная | J22: 2026 | K22: 45 | M22: открыть | N22: 2026 SF26-16 | P22: =IF(COUNTIFS($G$5:$G$66,G22,$H$5:$H$66,H22,$I$5:$I$66,I22,$C$5:$C$66,C22)>1,"повтор","") | Q22: =IF(C22<>"1:24","",IF(D22="","проверить",IF(D22<=Параметры!$B$12,"ок","дороже лимита"))) | R22: Новинка 2026, оценок ещё нет. На сайте масштаб 1:43 — в названии: модель дороже сезона 2025.
A23: Модели 1:43 — новинки 2026 | B23: Mercedes W17 — Антонелли #12 · масштаб 1:43 | C23: 1:43 | D23: 1489 | E23: =IF(D23="","",IF(D23<Параметры!$B$4,CEILING(D23*Параметры!$B$5,100)-10,IF(D23<=Параметры!$B$6,CEILING(D23*Параметры!$B$7,100)-10,CEILING(D23*Параметры!$B$8,100)-10))) -> 2990 | F23: =IF(D23="","",ROUND(E23*(1-Параметры!$B$9-Параметры!$B$10-Параметры!$B$11)-D23,0)) -> 1067 | G23: Mercedes W17 | H23: Антонелли #12 | I23: стандартная | J23: 2026 | K23: 31 | M23: открыть | N23: 2026 W17-12 | P23: =IF(COUNTIFS($G$5:$G$66,G23,$H$5:$H$66,H23,$I$5:$I$66,I23,$C$5:$C$66,C23)>1,"повтор","") | Q23: =IF(C23<>"1:24","",IF(D23="","проверить",IF(D23<=Параметры!$B$12,"ок","дороже лимита"))) | R23: Новинка 2026, оценок ещё нет. На сайте масштаб 1:43 — в названии: модель дороже сезона 2025.
A24: Модели 1:43 — новинки 2026 | B24: Mercedes W17 — Рассел #63 · масштаб 1:43 | C24: 1:43 | D24: 1489 | E24: =IF(D24="","",IF(D24<Параметры!$B$4,CEILING(D24*Параметры!$B$5,100)-10,IF(D24<=Параметры!$B$6,CEILING(D24*Параметры!$B$7,100)-10,CEILING(D24*Параметры!$B$8,100)-10))) -> 2990 | F24: =IF(D24="","",ROUND(E24*(1-Параметры!$B$9-Параметры!$B$10-Параметры!$B$11)-D24,0)) -> 1067 | G24: Mercedes W17 | H24: Рассел #63 | I24: стандартная | J24: 2026 | K24: 31 | M24: открыть | N24: 2026 W17-63 | P24: =IF(COUNTIFS($G$5:$G$66,G24,$H$5:$H$66,H24,$I$5:$I$66,I24,$C$5:$C$66,C24)>1,"повтор","") | Q24: =IF(C24<>"1:24","",IF(D24="","проверить",IF(D24<=Параметры!$B$12,"ок","дороже лимита"))) | R24: Новинка 2026, оценок ещё нет. На сайте масштаб 1:43 — в названии: модель дороже сезона 2025.
A25: Модели 1:24 | B25: Red Bull RB19 — Ферстаппен #1, ГП США | C25: 1:24 | D25: 2682 | E25: =IF(D25="","",IF(D25<Параметры!$B$4,CEILING(D25*Параметры!$B$5,100)-10,IF(D25<=Параметры!$B$6,CEILING(D25*Параметры!$B$7,100)-10,CEILING(D25*Параметры!$B$8,100)-10))) -> 4290 | F25: =IF(D25="","",ROUND(E25*(1-Параметры!$B$9-Параметры!$B$10-Параметры!$B$11)-D25,0)) -> 986 | G25: Red Bull RB19 | H25: Ферстаппен #1 | I25: ГП США | J25: 2023 | K25: 653 | L25: 4.9 | M25: открыть | N25: 1-24 2023 RB19-1USA | P25: =IF(COUNTIFS($G$5:$G$66,G25,$H$5:$H$66,H25,$I$5:$I$66,I25,$C$5:$C$66,C25)>1,"повтор","") | Q25: =IF(C25<>"1:24","",IF(D25="","проверить",IF(D25<=Параметры!$B$12,"ок","дороже лимита"))) -> ок | R25: Спецливрея RB19, придуманная фанатами (Остин 2023).
A26: Модели 1:24 | B26: Red Bull RB20 — Перес #11 | C26: 1:24 | D26: 2312 | E26: =IF(D26="","",IF(D26<Параметры!$B$4,CEILING(D26*Параметры!$B$5,100)-10,IF(D26<=Параметры!$B$6,CEILING(D26*Параметры!$B$7,100)-10,CEILING(D26*Параметры!$B$8,100)-10))) -> 3690 | F26: =IF(D26="","",ROUND(E26*(1-Параметры!$B$9-Параметры!$B$10-Параметры!$B$11)-D26,0)) -> 843 | G26: Red Bull RB20 | H26: Перес #11 | I26: стандартная | J26: 2024 | K26: 651 | L26: 4.9 | M26: открыть | N26: 1-24 2024 RB20-11 | O26: 502926 · 2409 ₽; 158416 · 2439 ₽ | P26: =IF(COUNTIFS($G$5:$G$66,G26,$H$5:$H$66,H26,$I$5:$I$66,I26,$C$5:$C$66,C26)>1,"повтор","") | Q26: =IF(C26<>"1:24","",IF(D26="","проверить",IF(D26<=Параметры!$B$12,"ок","дороже лимита"))) -> ок
A27: Модели 1:24 | B27: Red Bull RB20 — Ферстаппен #1 | C27: 1:24 | D27: 2409 | E27: =IF(D27="","",IF(D27<Параметры!$B$4,CEILING(D27*Параметры!$B$5,100)-10,IF(D27<=Параметры!$B$6,CEILING(D27*Параметры!$B$7,100)-10,CEILING(D27*Параметры!$B$8,100)-10))) -> 3890 | F27: =IF(D27="","",ROUND(E27*(1-Параметры!$B$9-Параметры!$B$10-Параметры!$B$11)-D27,0)) -> 917 | G27: Red Bull RB20 | H27: Ферстаппен #1 | I27: стандартная | J27: 2024 | K27: 78 | L27: 4.9 | M27: открыть | N27: 1-24 2024 RB20-1 | O27: 001375 · 2522 ₽; 158416 · 2659 ₽ | P27: =IF(COUNTIFS($G$5:$G$66,G27,$H$5:$H$66,H27,$I$5:$I$66,I27,$C$5:$C$66,C27)>1,"повтор","") | Q27: =IF(C27<>"1:24","",IF(D27="","проверить",IF(D27<=Параметры!$B$12,"ок","дороже лимита"))) -> ок
A28: Модели 1:24 | B28: Ferrari SF-24 — Леклер #16 | C28: 1:24 | D28: 2421 | E28: =IF(D28="","",IF(D28<Параметры!$B$4,CEILING(D28*Параметры!$B$5,100)-10,IF(D28<=Параметры!$B$6,CEILING(D28*Параметры!$B$7,100)-10,CEILING(D28*Параметры!$B$8,100)-10))) -> 3890 | F28: =IF(D28="","",ROUND(E28*(1-Параметры!$B$9-Параметры!$B$10-Параметры!$B$11)-D28,0)) -> 905 | G28: Ferrari SF-24 | H28: Леклер #16 | I28: стандартная | J28: 2024 | K28: 78 | L28: 4.9 | M28: открыть | N28: 1-24 2024 SF24-16 | O28: 158416 · 2461 ₽; 001375 · 2542 ₽ | P28: =IF(COUNTIFS($G$5:$G$66,G28,$H$5:$H$66,H28,$I$5:$I$66,I28,$C$5:$C$66,C28)>1,"повтор","") | Q28: =IF(C28<>"1:24","",IF(D28="","проверить",IF(D28<=Параметры!$B$12,"ок","дороже лимита"))) -> ок
A29: Модели 1:24 | B29: Ferrari SF-24 — Леклер #16, с надписью Leclerc | C29: 1:24 | D29: 2679 | E29: =IF(D29="","",IF(D29<Параметры!$B$4,CEILING(D29*Параметры!$B$5,100)-10,IF(D29<=Параметры!$B$6,CEILING(D29*Параметры!$B$7,100)-10,CEILING(D29*Параметры!$B$8,100)-10))) -> 4290 | F29: =IF(D29="","",ROUND(E29*(1-Параметры!$B$9-Параметры!$B$10-Параметры!$B$11)-D29,0)) -> 989 | G29: Ferrari SF-24 | H29: Леклер #16 | I29: с надписью Leclerc | J29: 2024 | K29: 653 | L29: 4.9 | M29: открыть | N29: 1-24 2024 SF24-161 | P29: =IF(COUNTIFS($G$5:$G$66,G29,$H$5:$H$66,H29,$I$5:$I$66,I29,$C$5:$C$66,C29)>1,"повтор","") | Q29: =IF(C29<>"1:24","",IF(D29="","проверить",IF(D29<=Параметры!$B$12,"ок","дороже лимита"))) -> ок | R29: Вариант «SF24-161» — версия с надписью Leclerc. Обычный SF-24 Леклера — отдельной строкой.
A30: Модели 1:24 | B30: Ferrari SF-24 — Сайнс #55 | C30: 1:24 | D30: 2439 | E30: =IF(D30="","",IF(D30<Параметры!$B$4,CEILING(D30*Параметры!$B$5,100)-10,IF(D30<=Параметры!$B$6,CEILING(D30*Параметры!$B$7,100)-10,CEILING(D30*Параметры!$B$8,100)-10))) -> 3990 | F30: =IF(D30="","",ROUND(E30*(1-Параметры!$B$9-Параметры!$B$10-Параметры!$B$11)-D30,0)) -> 972 | G30: Ferrari SF-24 | H30: Сайнс #55 | I30: стандартная | J30: 2024 | K30: 78 | L30: 4.9 | M30: открыть | N30: 1-24 2024 SF24-55 | P30: =IF(COUNTIFS($G$5:$G$66,G30,$H$5:$H$66,H30,$I$5:$I$66,I30,$C$5:$C$66,C30)>1,"повтор","") | Q30: =IF(C30<>"1:24","",IF(D30="","проверить",IF(D30<=Параметры!$B$12,"ок","дороже лимита"))) -> ок
A31: Модели 1:24 | B31: Mercedes W15 — Хэмилтон #44 | C31: 1:24 | D31: 2509 | E31: =IF(D31="","",IF(D31<Параметры!$B$4,CEILING(D31*Параметры!$B$5,100)-10,IF(D31<=Параметры!$B$6,CEILING(D31*Параметры!$B$7,100)-10,CEILING(D31*Параметры!$B$8,100)-10))) -> 4090 | F31: =IF(D31="","",ROUND(E31*(1-Параметры!$B$9-Параметры!$B$10-Параметры!$B$11)-D31,0)) -> 988 | G31: Mercedes W15 | H31: Хэмилтон #44 | I31: стандартная | J31: 2024 | K31: 651 | L31: 4.9 | M31: открыть | N31: 1-24 2024 W15-44 | O31: 502926 · 2611 ₽; 158416 · 2649 ₽ | P31: =IF(COUNTIFS($G$5:$G$66,G31,$H$5:$H$66,H31,$I$5:$I$66,I31,$C$5:$C$66,C31)>1,"повтор","") | Q31: =IF(C31<>"1:24","",IF(D31="","проверить",IF(D31<=Параметры!$B$12,"ок","дороже лимита"))) -> ок
A32: Модели 1:24 | B32: Mercedes W15 — Рассел #63 | C32: 1:24 | D32: 2509 | E32: =IF(D32="","",IF(D32<Параметры!$B$4,CEILING(D32*Параметры!$B$5,100)-10,IF(D32<=Параметры!$B$6,CEILING(D32*Параметры!$B$7,100)-10,CEILING(D32*Параметры!$B$8,100)-10))) -> 4090 | F32: =IF(D32="","",ROUND(E32*(1-Параметры!$B$9-Параметры!$B$10-Параметры!$B$11)-D32,0)) -> 988 | G32: Mercedes W15 | H32: Рассел #63 | I32: стандартная | J32: 2024 | K32: 651 | L32: 4.9 | M32: открыть | N32: 1-24 2024 W15-63 | P32: =IF(COUNTIFS($G$5:$G$66,G32,$H$5:$H$66,H32,$I$5:$I$66,I32,$C$5:$C$66,C32)>1,"повтор","") | Q32: =IF(C32<>"1:24","",IF(D32="","проверить",IF(D32<=Параметры!$B$12,"ок","дороже лимита"))) -> ок
A33: Модели 1:24 | B33: McLaren MCL38 — Норрис #4 | C33: 1:24 | D33: 1842 | E33: =IF(D33="","",IF(D33<Параметры!$B$4,CEILING(D33*Параметры!$B$5,100)-10,IF(D33<=Параметры!$B$6,CEILING(D33*Параметры!$B$7,100)-10,CEILING(D33*Параметры!$B$8,100)-10))) -> 2990 | F33: =IF(D33="","",ROUND(E33*(1-Параметры!$B$9-Параметры!$B$10-Параметры!$B$11)-D33,0)) -> 714 | G33: McLaren MCL38 | H33: Норрис #4 | I33: стандартная | J33: 2024 | K33: 150 | L33: 5 | M33: открыть | N33: Норрис #4 — выбрать в лоте | O33: 009441469506 · 2 699 ₽ | P33: =IF(COUNTIFS($G$5:$G$66,G33,$H$5:$H$66,H33,$I$5:$I$66,I33,$C$5:$C$66,C33)>1,"повтор","") | Q33: =IF(C33<>"1:24","",IF(D33="","проверить",IF(D33<=Параметры!$B$12,"ок","дороже лимита"))) -> ок | R33: Лот найден поиском aliexpress.ru, в CSV из Chrome его нет: проверить по фото, что ливрея обычная, а не «Майами», и цену варианта. Запасной: 1005009441469506 · 2 699 ₽, 503 заказа, 4.9.
A34: Модели 1:24 | B34: McLaren MCL38 — Пиастри #81 | C34: 1:24 | D34: 2549 | E34: =IF(D34="","",IF(D34<Параметры!$B$4,CEILING(D34*Параметры!$B$5,100)-10,IF(D34<=Параметры!$B$6,CEILING(D34*Параметры!$B$7,100)-10,CEILING(D34*Параметры!$B$8,100)-10))) -> 4090 | F34: =IF(D34="","",ROUND(E34*(1-Параметры!$B$9-Параметры!$B$10-Параметры!$B$11)-D34,0)) -> 948 | G34: McLaren MCL38 | H34: Пиастри #81 | I34: стандартная | J34: 2024 | K34: 651 | L34: 4.9 | M34: открыть | N34: 1-24 2024 MCL38-81 | P34: =IF(COUNTIFS($G$5:$G$66,G34,$H$5:$H$66,H34,$I$5:$I$66,I34,$C$5:$C$66,C34)>1,"повтор","") | Q34: =IF(C34<>"1:24","",IF(D34="","проверить",IF(D34<=Параметры!$B$12,"ок","дороже лимита"))) -> ок
A35: Модели 1:24 | B35: Aston Martin AMR25 — Алонсо #14 | C35: 1:24 | D35: 2631 | E35: =IF(D35="","",IF(D35<Параметры!$B$4,CEILING(D35*Параметры!$B$5,100)-10,IF(D35<=Параметры!$B$6,CEILING(D35*Параметры!$B$7,100)-10,CEILING(D35*Параметры!$B$8,100)-10))) -> 4290 | F35: =IF(D35="","",ROUND(E35*(1-Параметры!$B$9-Параметры!$B$10-Параметры!$B$11)-D35,0)) -> 1037 | G35: Aston Martin AMR25 | H35: Алонсо #14 | I35: стандартная | J35: 2025 | K35: 78 | L35: 4.9 | M35: открыть | N35: 1-24 2025 AMR25-14 | P35: =IF(COUNTIFS($G$5:$G$66,G35,$H$5:$H$66,H35,$I$5:$I$66,I35,$C$5:$C$66,C35)>1,"повтор","") | Q35: =IF(C35<>"1:24","",IF(D35="","проверить",IF(D35<=Параметры!$B$12,"ок","дороже лимита"))) -> ок
A36: Модели 1:24 | B36: Aston Martin AMR25 — Стролл #18 | C36: 1:24 | D36: 2401 | E36: =IF(D36="","",IF(D36<Параметры!$B$4,CEILING(D36*Параметры!$B$5,100)-10,IF(D36<=Параметры!$B$6,CEILING(D36*Параметры!$B$7,100)-10,CEILING(D36*Параметры!$B$8,100)-10))) -> 3890 | F36: =IF(D36="","",ROUND(E36*(1-Параметры!$B$9-Параметры!$B$10-Параметры!$B$11)-D36,0)) -> 925 | G36: Aston Martin AMR25 | H36: Стролл #18 | I36: стандартная | J36: 2025 | K36: 78 | L36: 4.9 | M36: открыть | N36: 1-24 2025 AMR25-18 | O36: 158416 · 2430 ₽; 001375 · 2522 ₽ | P36: =IF(COUNTIFS($G$5:$G$66,G36,$H$5:$H$66,H36,$I$5:$I$66,I36,$C$5:$C$66,C36)>1,"повтор","") | Q36: =IF(C36<>"1:24","",IF(D36="","проверить",IF(D36<=Параметры!$B$12,"ок","дороже лимита"))) -> ок
A37: Конструкторы — лицензия CaDA | B37: CaDA BWT Alpine A525 | C37: 1:24 | D37: 4524 | E37: =IF(D37="","",IF(D37<Параметры!$B$4,CEILING(D37*Параметры!$B$5,100)-10,IF(D37<=Параметры!$B$6,CEILING(D37*Параметры!$B$7,100)-10,CEILING(D37*Параметры!$B$8,100)-10))) -> 7290 | F37: =IF(D37="","",ROUND(E37*(1-Параметры!$B$9-Параметры!$B$10-Параметры!$B$11)-D37,0)) -> 1709 | G37: Alpine A525 | H37: — | I37: CaDA | J37: 2025 | K37: 268 | L37: 4.9 | M37: открыть | N37: проверить | P37: =IF(COUNTIFS($G$5:$G$66,G37,$H$5:$H$66,H37,$I$5:$I$66,I37,$C$5:$C$66,C37)>1,"повтор","") | Q37: =IF(C37<>"1:24","",IF(D37="","проверить",IF(D37<=Параметры!$B$12,"ок","дороже лимита"))) -> дороже лимита | R37: Официальная лицензия Alpine. Цена — верхняя оценка (зачёркнутая цена), реальная может быть до двух раз ниже. Вариант «с коробкой» и его цену не проверяли: в CSV из Chrome этого лота нет.
A38: Конструкторы — лицензия CaDA | B38: CaDA Kick Sauber C44 | C38: 1:24 | D38: 6648 | E38: =IF(D38="","",IF(D38<Параметры!$B$4,CEILING(D38*Параметры!$B$5,100)-10,IF(D38<=Параметры!$B$6,CEILING(D38*Параметры!$B$7,100)-10,CEILING(D38*Параметры!$B$8,100)-10))) -> 10690 | F38: =IF(D38="","",ROUND(E38*(1-Параметры!$B$9-Параметры!$B$10-Параметры!$B$11)-D38,0)) -> 2492 | G38: Kick Sauber C44 | H38: — | I38: CaDA | J38: 2024 | K38: 340 | L38: 4.7 | M38: открыть | N38: проверить | P38: =IF(COUNTIFS($G$5:$G$66,G38,$H$5:$H$66,H38,$I$5:$I$66,I38,$C$5:$C$66,C38)>1,"повтор","") | Q38: =IF(C38<>"1:24","",IF(D38="","проверить",IF(D38<=Параметры!$B$12,"ок","дороже лимита"))) -> дороже лимита | R38: Официальная лицензия Sauber. Цена — верхняя оценка (зачёркнутая цена), реальная может быть до двух раз ниже. Вариант «с коробкой» и его цену не проверяли: в CSV из Chrome этого лота нет.
A39: Конструкторы — реплика | B39: Red Bull RB21 — реплика 1:8 | C39: 1:8 | D39: 2849 | E39: =IF(D39="","",IF(D39<Параметры!$B$4,CEILING(D39*Параметры!$B$5,100)-10,IF(D39<=Параметры!$B$6,CEILING(D39*Параметры!$B$7,100)-10,CEILING(D39*Параметры!$B$8,100)-10))) -> 4590 | F39: =IF(D39="","",ROUND(E39*(1-Параметры!$B$9-Параметры!$B$10-Параметры!$B$11)-D39,0)) -> 1075 | G39: Red Bull RB21 | H39: — | I39: реплика | J39: 2025 | K39: 136 | L39: 4.9 | M39: открыть | N39: проверить | O39: 310056041 · 4699 ₽ | P39: =IF(COUNTIFS($G$5:$G$66,G39,$H$5:$H$66,H39,$I$5:$I$66,I39,$C$5:$C$66,C39)>1,"повтор","") | Q39: =IF(C39<>"1:24","",IF(D39="","проверить",IF(D39<=Параметры!$B$12,"ок","дороже лимита"))) | R39: Цена — верхняя оценка (зачёркнутая): в выдаче была только цена для новичков, реальная может быть до двух раз ниже. Вариант «с коробкой» и его цену не проверяли: в CSV из Chrome этого лота нет.
A40: Конструкторы — реплика | B40: Ferrari SF-25 — реплика 1:8 | C40: 1:8 | D40: 3044 | E40: =IF(D40="","",IF(D40<Параметры!$B$4,CEILING(D40*Параметры!$B$5,100)-10,IF(D40<=Параметры!$B$6,CEILING(D40*Параметры!$B$7,100)-10,CEILING(D40*Параметры!$B$8,100)-10))) -> 4890 | F40: =IF(D40="","",ROUND(E40*(1-Параметры!$B$9-Параметры!$B$10-Параметры!$B$11)-D40,0)) -> 1137 | G40: Ferrari SF-25 | H40: — | I40: реплика | J40: 2025 | K40: 75 | M40: открыть | N40: проверить | O40: 682211506 · 5967 ₽ | P40: =IF(COUNTIFS($G$5:$G$66,G40,$H$5:$H$66,H40,$I$5:$I$66,I40,$C$5:$C$66,C40)>1,"повтор","") | Q40: =IF(C40<>"1:24","",IF(D40="","проверить",IF(D40<=Параметры!$B$12,"ок","дороже лимита"))) | R40: Вариант «с коробкой» и его цену не проверяли: в CSV из Chrome этого лота нет.
...

Sheet Мерч и кепки
A1: TMFF — одежда в стиле командной формы
A2: Поиск aliexpress.com 25.09.2026. Цена пересчитана из $ по курсу с листа «Параметры»; жёлтая — верхняя оценка (в выдаче была только цена для новичков), реальная может быть до двух раз ниже. Прибыль — с резервом на возвраты по одежде (10 %).
A3: Только вещи в стиле официальной формы команд, на сайте — с пометкой «Реплика». Командные кепки и худи Ferrari, Red Bull, Mercedes и McLaren на aliexpress.com почти не показываются — стоит поискать их на aliexpress.ru. Номер № — на картинке merch-candidates.jpg.
A4: № | B4: Команда | C4: Название на сайте | D4: Вещь | E4: Команда | F4: Цена на Ali, ₽ | G4: Наша цена, ₽ | H4: Прибыль с шт., ₽ | I4: Заказов | J4: Рейтинг | K4: Лот | L4: Заметки и что проверить
A5: 1 | B5: Ferrari | C5: Футболка Ferrari · Хэмилтон 44 | D5: футболка | E5: Ferrari | F5: 792 | G5: =IF(F5="","",IF(F5<Параметры!$B$4,CEILING(F5*Параметры!$B$5,100)-10,IF(F5<=Параметры!$B$6,CEILING(F5*Параметры!$B$7,100)-10,CEILING(F5*Параметры!$B$8,100)-10))) -> 1590 | H5: =IF(F5="","",ROUND(G5*(1-Параметры!$B$9-Параметры!$B$10-Параметры!$B$14)-F5,0)) -> 488 | I5: 752 | J5: 4.5 | K5: открыть | L5: Стиль формы Ferrari 2026 с логотипами партнёров.
A6: 2 | B6: Ferrari | C6: Худи Ferrari · Хэмилтон 44 | D6: кофта | E6: Ferrari | F6: 3705 | G6: =IF(F6="","",IF(F6<Параметры!$B$4,CEILING(F6*Параметры!$B$5,100)-10,IF(F6<=Параметры!$B$6,CEILING(F6*Параметры!$B$7,100)-10,CEILING(F6*Параметры!$B$8,100)-10))) -> 5990 | H6: =IF(F6="","",ROUND(G6*(1-Параметры!$B$9-Параметры!$B$10-Параметры!$B$14)-F6,0)) -> 1117 | I6: 7 | K6: открыть | L6: Та же расцветка, что у футболки. Цена — верхняя оценка.
A7: 3 | B7: Ferrari | C7: Кепка Ferrari · Хэмилтон 44 | D7: кепка | E7: Ferrari | F7: 1909 | G7: =IF(F7="","",IF(F7<Параметры!$B$4,CEILING(F7*Параметры!$B$5,100)-10,IF(F7<=Параметры!$B$6,CEILING(F7*Параметры!$B$7,100)-10,CEILING(F7*Параметры!$B$8,100)-10))) -> 3090 | H7: =IF(F7="","",ROUND(G7*(1-Параметры!$B$9-Параметры!$B$10-Параметры!$B$14)-F7,0)) -> 578 | I7: 9 | K7: открыть | L7: Мало заказов — сначала образец. Цена — верхняя оценка.
A8: 4 | B8: McLaren | C8: Футболка McLaren · Норрис 4 | D8: футболка | E8: McLaren | F8: 773 | G8: =IF(F8="","",IF(F8<Параметры!$B$4,CEILING(F8*Параметры!$B$5,100)-10,IF(F8<=Параметры!$B$6,CEILING(F8*Параметры!$B$7,100)-10,CEILING(F8*Параметры!$B$8,100)-10))) -> 1590 | H8: =IF(F8="","",ROUND(G8*(1-Параметры!$B$9-Параметры!$B$10-Параметры!$B$14)-F8,0)) -> 507 | I8: 63 | J8: 4.8 | K8: открыть | L8: Форма McLaren 2025, номер 4.
A9: 5 | B9: McLaren | C9: Поло McLaren · Норрис 1 | D9: футболка | E9: McLaren | F9: 1342 | G9: =IF(F9="","",IF(F9<Параметры!$B$4,CEILING(F9*Параметры!$B$5,100)-10,IF(F9<=Параметры!$B$6,CEILING(F9*Параметры!$B$7,100)-10,CEILING(F9*Параметры!$B$8,100)-10))) -> 2690 | H9: =IF(F9="","",ROUND(G9*(1-Параметры!$B$9-Параметры!$B$10-Параметры!$B$14)-F9,0)) -> 823 | I9: 78 | J9: 4.1 | K9: открыть | L9: Командное поло 2026, номер 1.
A10: 6 | B10: McLaren | C10: Кепка McLaren · Норрис 4 | D10: кепка | E10: McLaren | F10: 670 | G10: =IF(F10="","",IF(F10<Параметры!$B$4,CEILING(F10*Параметры!$B$5,100)-10,IF(F10<=Параметры!$B$6,CEILING(F10*Параметры!$B$7,100)-10,CEILING(F10*Параметры!$B$8,100)-10))) -> 1390 | H10: =IF(F10="","",ROUND(G10*(1-Параметры!$B$9-Параметры!$B$10-Параметры!$B$14)-F10,0)) -> 449 | I10: 10 | K10: открыть | L10: Кепка в стиле кепки пилота; мало заказов. Цена — верхняя оценка.
A11: 7 | B11: Red Bull Racing | C11: Футболка Red Bull Racing · Ферстаппен 3 | D11: футболка | E11: Red Bull | F11: 1376 | G11: =IF(F11="","",IF(F11<Параметры!$B$4,CEILING(F11*Параметры!$B$5,100)-10,IF(F11<=Параметры!$B$6,CEILING(F11*Параметры!$B$7,100)-10,CEILING(F11*Параметры!$B$8,100)-10))) -> 2790 | H11: =IF(F11="","",ROUND(G11*(1-Параметры!$B$9-Параметры!$B$10-Параметры!$B$14)-F11,0)) -> 870 | I11: 22 | K11: открыть | L11: Форма Red Bull 2026, номер 3. Цена — верхняя оценка. Запасной: 3256812989321292.
A12: 8 | B12: Red Bull Racing | C12: Кепка Red Bull Racing · Ферстаппен 1 | D12: кепка | E12: Red Bull | F12: 1932 | G12: =IF(F12="","",IF(F12<Параметры!$B$4,CEILING(F12*Параметры!$B$5,100)-10,IF(F12<=Параметры!$B$6,CEILING(F12*Параметры!$B$7,100)-10,CEILING(F12*Параметры!$B$8,100)-10))) -> 3090 | H12: =IF(F12="","",ROUND(G12*(1-Параметры!$B$9-Параметры!$B$10-Параметры!$B$14)-F12,0)) -> 555 | I12: 4 | K12: открыть | L12: Кепка пилота с номером 1. Мало заказов — сначала образец. Цена — верхняя оценка.
A13: 9 | B13: Mercedes | C13: Футболка Mercedes · Рассел 63 | D13: футболка | E13: Mercedes | F13: 1661 | G13: =IF(F13="","",IF(F13<Параметры!$B$4,CEILING(F13*Параметры!$B$5,100)-10,IF(F13<=Параметры!$B$6,CEILING(F13*Параметры!$B$7,100)-10,CEILING(F13*Параметры!$B$8,100)-10))) -> 2690 | H13: =IF(F13="","",ROUND(G13*(1-Параметры!$B$9-Параметры!$B$10-Параметры!$B$14)-F13,0)) -> 504 | I13: 76 | K13: открыть | L13: Форма Mercedes 2026 с логотипами партнёров. Цена — верхняя оценка. Запасной: 3256811449048467.
A14: 10 | B14: Mercedes | C14: Флисовая кофта Mercedes | D14: кофта | E14: Mercedes | F14: 2656 | G14: =IF(F14="","",IF(F14<Параметры!$B$4,CEILING(F14*Параметры!$B$5,100)-10,IF(F14<=Параметры!$B$6,CEILING(F14*Параметры!$B$7,100)-10,CEILING(F14*Параметры!$B$8,100)-10))) -> 4290 | H14: =IF(F14="","",ROUND(G14*(1-Параметры!$B$9-Параметры!$B$10-Параметры!$B$14)-F14,0)) -> 797 | I14: 14 | K14: открыть | L14: Флиска на молнии с логотипом Petronas.
A15: 11 | B15: Aston Martin | C15: Кепка Aston Martin · Алонсо 14 | D15: кепка | E15: Aston Martin | F15: 986 | G15: =IF(F15="","",IF(F15<Параметры!$B$4,CEILING(F15*Параметры!$B$5,100)-10,IF(F15<=Параметры!$B$6,CEILING(F15*Параметры!$B$7,100)-10,CEILING(F15*Параметры!$B$8,100)-10))) -> 1990 | H15: =IF(F15="","",ROUND(G15*(1-Параметры!$B$9-Параметры!$B$10-Параметры!$B$14)-F15,0)) -> 616 | I15: 500 | J15: 4.8 | K15: открыть | L15: Самая продаваемая командная кепка в выдаче. Цена — верхняя оценка. Запасной: 3256810368072176.
A16: 12 | B16: Aston Martin | C16: Футболка Aston Martin · Алонсо 14 | D16: футболка | E16: Aston Martin | F16: 726 | G16: =IF(F16="","",IF(F16<Параметры!$B$4,CEILING(F16*Параметры!$B$5,100)-10,IF(F16<=Параметры!$B$6,CEILING(F16*Параметры!$B$7,100)-10,CEILING(F16*Параметры!$B$8,100)-10))) -> 1490 | H16: =IF(F16="","",ROUND(G16*(1-Параметры!$B$9-Параметры!$B$10-Параметры!$B$14)-F16,0)) -> 473 | I16: 194 | J16: 4.2 | K16: открыть | L16: Форма Aston Martin, номер 14.
A17: 13 | B17: Williams | C17: Футболка Williams · Сайнс 55 | D17: футболка | E17: Williams | F17: 738 | G17: =IF(F17="","",IF(F17<Параметры!$B$4,CEILING(F17*Параметры!$B$5,100)-10,IF(F17<=Параметры!$B$6,CEILING(F17*Параметры!$B$7,100)-10,CEILING(F17*Параметры!$B$8,100)-10))) -> 1490 | H17: =IF(F17="","",ROUND(G17*(1-Параметры!$B$9-Параметры!$B$10-Параметры!$B$14)-F17,0)) -> 461 | I17: 104 | J17: 4.3 | K17: открыть | L17: Форма Atlassian Williams 2026. Цена — верхняя оценка. Запасной: 3256809585305917.
A18: 14 | B18: Williams | C18: Поло Williams · Сайнс 55 | D18: футболка | E18: Williams | F18: 1119 | G18: =IF(F18="","",IF(F18<Параметры!$B$4,CEILING(F18*Параметры!$B$5,100)-10,IF(F18<=Параметры!$B$6,CEILING(F18*Параметры!$B$7,100)-10,CEILING(F18*Параметры!$B$8,100)-10))) -> 2290 | H18: =IF(F18="","",ROUND(G18*(1-Параметры!$B$9-Параметры!$B$10-Параметры!$B$14)-F18,0)) -> 724 | I18: 121 | J18: 4.1 | K18: открыть | L18: Командное поло 2026. Цена — верхняя оценка.
A19: 15 | B19: Williams | C19: Кепка Williams · Сайнс 55 | D19: кепка | E19: Williams | F19: 710 | G19: =IF(F19="","",IF(F19<Параметры!$B$4,CEILING(F19*Параметры!$B$5,100)-10,IF(F19<=Параметры!$B$6,CEILING(F19*Параметры!$B$7,100)-10,CEILING(F19*Параметры!$B$8,100)-10))) -> 1490 | H19: =IF(F19="","",ROUND(G19*(1-Параметры!$B$9-Параметры!$B$10-Параметры!$B$14)-F19,0)) -> 489 | I19: 88 | J19: 4.3 | K19: открыть | L19: Кепка пилота Карлоса Сайнса. Цена — верхняя оценка.
A20: 16 | B20: Audi | C20: Поло Audi | D20: футболка | E20: Audi | F20: 782 | G20: =IF(F20="","",IF(F20<Параметры!$B$4,CEILING(F20*Параметры!$B$5,100)-10,IF(F20<=Параметры!$B$6,CEILING(F20*Параметры!$B$7,100)-10,CEILING(F20*Параметры!$B$8,100)-10))) -> 1590 | H20: =IF(F20="","",ROUND(G20*(1-Параметры!$B$9-Параметры!$B$10-Параметры!$B$14)-F20,0)) -> 498 | I20: 131 | K20: открыть | L20: Поло Audi Sport, первый сезон Audi в Формуле 1.
A21: 17 | B21: Haas | C21: Худи Haas | D21: кофта | E21: Haas | F21: 1753 | G21: =IF(F21="","",IF(F21<Параметры!$B$4,CEILING(F21*Параметры!$B$5,100)-10,IF(F21<=Параметры!$B$6,CEILING(F21*Параметры!$B$7,100)-10,CEILING(F21*Параметры!$B$8,100)-10))) -> 2890 | H21: =IF(F21="","",ROUND(G21*(1-Параметры!$B$9-Параметры!$B$10-Параметры!$B$14)-F21,0)) -> 573 | I21: 4 | K21: открыть | L21: Худи с логотипом Haas. Мало заказов — сначала образец.
A22: 18 | B22: Ferrari | C22: Футболка Ferrari · Леклер 16 | D22: футболка | E22: Ferrari | F22: 1331 | G22: =IF(F22="","",IF(F22<Параметры!$B$4,CEILING(F22*Параметры!$B$5,100)-10,IF(F22<=Параметры!$B$6,CEILING(F22*Параметры!$B$7,100)-10,CEILING(F22*Параметры!$B$8,100)-10))) -> 2690 | H22: =IF(F22="","",ROUND(G22*(1-Параметры!$B$9-Параметры!$B$10-Параметры!$B$14)-F22,0)) -> 834 | I22: 32 | K22: открыть | L22: Та же форма Ferrari 2026, вариант Леклера. Цена — верхняя оценка.
A23: 19 | B23: Ferrari | C23: Футболка Ferrari | D23: футболка | E23: Ferrari | F23: 2027 | G23: =IF(F23="","",IF(F23<Параметры!$B$4,CEILING(F23*Параметры!$B$5,100)-10,IF(F23<=Параметры!$B$6,CEILING(F23*Параметры!$B$7,100)-10,CEILING(F23*Параметры!$B$8,100)-10))) -> 3290 | H23: =IF(F23="","",ROUND(G23*(1-Параметры!$B$9-Параметры!$B$10-Параметры!$B$14)-F23,0)) -> 621 | I23: 11 | K23: открыть | L23: Командная футболка без номера пилота. Цена — верхняя оценка.
A24: 20 | B24: Ferrari | C24: Футболка Ferrari «Монца» | D24: футболка | E24: Ferrari | F24: 2027 | G24: =IF(F24="","",IF(F24<Параметры!$B$4,CEILING(F24*Параметры!$B$5,100)-10,IF(F24<=Параметры!$B$6,CEILING(F24*Параметры!$B$7,100)-10,CEILING(F24*Параметры!$B$8,100)-10))) -> 3290 | H24: =IF(F24="","",ROUND(G24*(1-Параметры!$B$9-Параметры!$B$10-Параметры!$B$14)-F24,0)) -> 621 | I24: 9 | K24: открыть | L24: Спецвыпуск к Гран-при Италии, синяя. Год уточнить по фото. Цена — верхняя оценка.
A25: 21 | B25: Ferrari | C25: Кепка Ferrari «Монца» | D25: кепка | E25: Ferrari | F25: 1927 | G25: =IF(F25="","",IF(F25<Параметры!$B$4,CEILING(F25*Параметры!$B$5,100)-10,IF(F25<=Параметры!$B$6,CEILING(F25*Параметры!$B$7,100)-10,CEILING(F25*Параметры!$B$8,100)-10))) -> 3090 | H25: =IF(F25="","",ROUND(G25*(1-Параметры!$B$9-Параметры!$B$10-Параметры!$B$14)-F25,0)) -> 560 | I25: 4 | K25: открыть | L25: Синяя кепка спецвыпуска к Гран-при Италии. Мало заказов. Цена — верхняя оценка.
A26: 22 | B26: Red Bull Racing | C26: Лонгслив Red Bull Racing · Перес 11 | D26: футболка | E26: Red Bull | F26: 1820 | G26: =IF(F26="","",IF(F26<Параметры!$B$4,CEILING(F26*Параметры!$B$5,100)-10,IF(F26<=Параметры!$B$6,CEILING(F26*Параметры!$B$7,100)-10,CEILING(F26*Параметры!$B$8,100)-10))) -> 2990 | H26: =IF(F26="","",ROUND(G26*(1-Параметры!$B$9-Параметры!$B$10-Параметры!$B$14)-F26,0)) -> 587 | I26: 42 | K26: открыть | L26: Форма Red Bull с длинным рукавом, номер Переса — сезоны 2021–2024. Цена — верхняя оценка.
A27: 23 | B27: Red Bull Racing | C27: Кепка Red Bull Racing · Перес 11 | D27: кепка | E27: Red Bull | F27: 588 | G27: =IF(F27="","",IF(F27<Параметры!$B$4,CEILING(F27*Параметры!$B$5,100)-10,IF(F27<=Параметры!$B$6,CEILING(F27*Параметры!$B$7,100)-10,CEILING(F27*Параметры!$B$8,100)-10))) -> 1190 | H27: =IF(F27="","",ROUND(G27*(1-Параметры!$B$9-Параметры!$B$10-Параметры!$B$14)-F27,0)) -> 370 | I27: 33 | K27: открыть | L27: Кепка пилота Серхио Переса. Цена — верхняя оценка.
A28: 24 | B28: Mercedes | C28: Футболка Mercedes · Антонелли 12 | D28: футболка | E28: Mercedes | F28: 1083 | G28: =IF(F28="","",IF(F28<Параметры!$B$4,CEILING(F28*Параметры!$B$5,100)-10,IF(F28<=Параметры!$B$6,CEILING(F28*Параметры!$B$7,100)-10,CEILING(F28*Параметры!$B$8,100)-10))) -> 2190 | H28: =IF(F28="","",ROUND(G28*(1-Параметры!$B$9-Параметры!$B$10-Параметры!$B$14)-F28,0)) -> 680 | I28: 96 | J28: 4.4 | K28: открыть | L28: Форма Mercedes 2026, номер Антонелли.
A29: 25 | B29: Mercedes | C29: Кепка Mercedes · Хэмилтон 44 | D29: кепка | E29: Mercedes | F29: 301 | G29: =IF(F29="","",IF(F29<Параметры!$B$4,CEILING(F29*Параметры!$B$5,100)-10,IF(F29<=Параметры!$B$6,CEILING(F29*Параметры!$B$7,100)-10,CEILING(F29*Параметры!$B$8,100)-10))) -> 690 | H29: =IF(F29="","",ROUND(G29*(1-Параметры!$B$9-Параметры!$B$10-Параметры!$B$14)-F29,0)) -> 254 | I29: 6 | K29: открыть | L29: Кепка с номером 44 в стиле эпохи Хэмилтона в Mercedes.
A31: Итого
B32: Позиций | C32: =COUNTA(C5:C29) -> 25
B33: футболка | C33: =COUNTIF($D$5:$D$29,"футболка") -> 14
B34: кофта | C34: =COUNTIF($D$5:$D$29,"кофта") -> 3
B35: кепка | C35: =COUNTIF($D$5:$D$29,"кепка") -> 8
B36: Средняя прибыль, ₽ | C36: =IFERROR(ROUND(AVERAGE($H$5:$H$29),0),"") -> 602

Sheet Мерч — все лоты
A1: Все найденные лоты одежды и кепок — 739
A2: Тип, команда и риск определены по названию лота автоматически — могут быть ошибки. Отсортировано по заказам. Фильтр в заголовке — чтобы смотреть по вещи, команде или риску.
A4: Вещь | B4: Команда | C4: Риск по названию | D4: Название лота | E4: Цена, ₽ | F4: Для новичков, $ | G4: Заказов | H4: Рейтинг | I4: Лот | J4: Запрос
A5: кепка | B5: Легенды | C5: имя/образ пилота | D5: New Ayrton Senna Racer Fashion Embroidery Cap Outdoor Sun Protection Team Baseball Cap | E5: 1087 | F5: 1.09 | G5: 10000 | H5: 4.7 | I5: открыть | J5: f1 cap
A6: футболка | B6: — | C6: своя печать | D6: Custom Cotton Customized Print Short Sleeve T Shirt Summer Tops Tees DIY Your Like Photo Or Logo Cotton T-shirt Men Clothing | E6: 1156 | F6: 1.28 | G6: 10000 | H6: 4.6 | I6: открыть | J6: custom print t shirt heavyweight cotton
A7: футболка | B7: — | C7: своя печать | D7: Men's Cotton T-shirt Personalized Your Design Here Custom Text Tshirt for Men Add Your Own Design Fashion T Shirt Men Clothing | E7: 1005 | G7: 5000 | H7: 4.7 | I7: открыть | J7: ferrari f1 t shirt
A8: футболка | B8: — | C8: своя печать | D8: Men's Personalized Cotton T-shirt Custom Text Name Tsihrts Add Your Own Message Fashion men tshirt bigger size 4XL 5XL | E8: 994 | G8: 5000 | H8: 4.7 | I8: открыть | J8: ferrari f1 t shirt
A9: футболка | B9: — | C9: своя печать | D9: Custom T-shirt Customized Print T Shirt Men Women Personalized Tops Tees DIY Your Like Photo Or Logo Cotton T-shirt Men Clothing | E9: 1201 | F9: 1.13 | G9: 5000 | H9: 4.7 | I9: открыть | J9: red bull racing t shirt
A10: футболка | B10: — | C10: своя печать | D10: 180g Custom Women Men Customised Printed 100% Cotton Short Sleeve Your Logo Photo Brand Text Tee Personalize Graphic Clothing | E10: 789 | F10: 3.37 | G10: 5000 | H10: 4.9 | I10: открыть | J10: custom print t shirt heavyweight cotton
A11: футболка | B11: — | C11: своя печать | D11: 100% Cotton T-shirt Custom Logo Street Trend Short Sleeve T-shirt Embroidery Design European American Size Tops Printing Pattern | E11: 1449 | G11: 5000 | H11: 4.8 | I11: открыть | J11: custom print t shirt heavyweight cotton
A12: кофта | B12: — | C12: своя печать | D12: DIY Custom Your Brand LOGO Men Women Casual Hoodie Top Solid Color Pullover Street Personality Sweatshirt Custom Gifts | E12: 2593 | F12: 8.16 | G12: 5000 | H12: 4.8 | I12: открыть | J12: custom logo hoodie heavyweight
A13: футболка | B13: — | C13: своя печать | D13: Custom T Shirt Make Your Design Logo Text Front And Back T-shirt Men Print Cotton Tshirt Personalized Gift Customized Tees Tops | E13: 1186 | F13: 0.99 | G13: 4000 | H13: 4.7 | I13: открыть | J13: ferrari f1 t shirt
A14: поло | B14: — | C14: своя печать | D14: Customized Logo Breathable Polo Shirt Casual Company Group Clothing Lapel Short Sleeve Polo Shirts Work Clothes Print Embroidery | E14: 1778 | F14: 0.99 | G14: 4000 | H14: 4.3 | I14: открыть | J14: ferrari f1 t shirt
A15: футболка | B15: — | C15: своя печать | D15: Custom-Made Men's T-Shirts Are Suitable for Team Gatherings, Gyms, and Sports Cotton Round-Neck Short-Sleeved Shirts | E15: 1818 | F15: 4.15 | G15: 4000 | H15: 4.6 | I15: открыть | J15: red bull racing t shirt
A16: футболка | B16: — | C16: своя печать | D16: Customized Print T Shirt Men Women Custom Cotton Tops Tees DIY Your Like Photo Or Logo Cotton T-shirt Personalized Men Clothing | E16: 485 | G16: 4000 | H16: 4.6 | I16: открыть | J16: custom print t shirt heavyweight cotton
A17: футболка | B17: — | C17: своя печать | D17: Customized Printed Leisure T Shirt Tee DIY Your Own Design Like Photo Or Logo White T-shirt Fashion Custom Men's Tops Tshirt | E17: 1265 | G17: 4000 | H17: 4.9 | I17: открыть | J17: custom print t shirt heavyweight cotton
A18: футболка | B18: — | C18: своя печать | D18: Custom Unisex Tshirt Add Your Own Message Cotton O Neck Top Tees Bigger Size Gift Custom Unisex Personalized Tshirts 4XL 5XL | E18: 771 | G18: 4000 | H18: 4.7 | I18: открыть | J18: custom print t shirt heavyweight cotton
A19: кепка | B19: — | C19: своя печать | D19: SLECKTON Custom Baseball Cap Fashion DIY Letter Embroidery Hats for Women and Men Cotton Design LOGO Wholesale Unisex Caps | E19: 1087 | F19: 1.23 | G19: 3000 | H19: 4.8 | I19: открыть | J19: ferrari f1 cap
A20: футболка | B20: — | C20: своя печать | D20: Add Your Own Custom Text Name Personalized Message Men's T Shirt Casual Dress High Quality MensT-shirt5xL | E20: 549 | G20: 3000 | H20: 4.8 | I20: открыть | J20: ferrari f1 t shirt
A21: футболка | B21: — | C21: своя печать | D21: New Custom Compression T Shirt Your Design Logo Top Men Women Print Original Design Tshirts Jogging Workout Gym Quick Dry Tshirt | E21: 848 | F21: 0.99 | G21: 3000 | H21: 4.8 | I21: открыть | J21: ferrari f1 t shirt
A22: поло | B22: — | C22: своя печать | D22: Summer Casual Cheap POLO Shirt Personal Company Logo Customization Embroidery Printing Personalized Design Top | E22: 851 | F22: 2.29 | G22: 3000 | H22: 4.7 | I22: открыть | J22: red bull racing t shirt
A23: кепка | B23: — | C23: своя печать | D23: 1 Piece Summer Trucker Hat Custom Logo Men Women Net Polyester Baseball Cap Print Mesh Dad Hats Adjustable Sun Hat Visor | E23: 765 | F23: 1.09 | G23: 2000 | H23: 4.6 | I23: открыть | J23: ferrari f1 cap
A24: кепка | B24: — | C24: своя печать | D24: SLECKTON Custom Logo High-quality Suede Mesh Baseball Hat Letter Embroidery Brand Design Outdoor Sport Cap Wholesale Fashion | E24: 1364 | F24: 1.94 | G24: 2000 | H24: 4.7 | I24: открыть | J24: custom logo embroidery baseball cap
A25: футболка | B25: — | C25: своя печать | D25: Your Design Here T Shirts Cotton Custom T-Shirt Make Your Design Logo Text for Men and Women Personalized Tshirt Summer Presents | E25: 1070 | G25: 2000 | H25: 4.8 | I25: открыть | J25: ferrari f1 t shirt
A26: футболка | B26: — | C26: своя печать | D26: UE Size Custom Team T-shirt for Women, Add Your Own Design in Front and Back, Print and Text, High-quality T-shirt for Men | E26: 723 | F26: 0.99 | G26: 2000 | H26: 4.6 | I26: открыть | J26: ferrari f1 t shirt
A27: футболка | B27: — | C27: своя печать | D27: 3d Printing Custom T-shirts Summer Plus Size T-shirt Design E-sports Jersey Customization Sports Outdoor Cool Round Neck Tops | E27: 584 | G27: 2000 | I27: открыть | J27: ferrari f1 t shirt
A28: кофта | B28: — | C28: своя печать | D28: Personalized DIY Fashion T-Shirts Polyester Fabric Comfortable Breathable Sweatshirts High Quality Unisex Customized Tops | E28: 614 | G28: 2000 | H28: 4.9 | I28: открыть | J28: ferrari f1 t shirt
A29: футболка | B29: — | C29: своя печать | D29: Custom Your Exclusive 3D All Over Print T Shirt For Men Fashion Hip Hop Short Sleeve Tops Men Women Kids DIY Wholesale T-shirts | E29: 467 | F29: 1.09 | G29: 2000 | H29: 4.9 | I29: открыть | J29: mclaren f1 t shirt
A30: кепка | B30: — | C30: своя печать | D30: Custom Text Logo Embroidery Vintage Washed Cotton Baseball Cap Fashion Women Men Hat Sport Visors Snapback Cap Sun Hat | E30: 585 | G30: 2000 | H30: 4.7 | I30: открыть | J30: custom logo embroidery baseball cap
A31: кепка | B31: — | C31: своя печать | D31: SLECKTON Custom Cap Logo Embroidery Retro Baseball Cap for Men and Women DIY Design Letter Hat Customize Graphic Print Wholesale | E31: 573 | G31: 2000 | H31: 4.8 | I31: открыть | J31: custom logo embroidery baseball cap
A32: кепка | B32: — | C32: своя печать | D32: Custom Embroidered Baseball Caps For Men Woman Hat Custom Logo Men's Cap Snapback Embroidery Print Text Design Trucker Mesh Hats | E32: 377 | G32: 2000 | H32: 4.8 | I32: открыть | J32: custom logo embroidery baseball cap
A33: футболка | B33: — | C33: своя печать | D33: Personalized Custom Print Summer Y2K Team T-Shirt Cotton Casual Loose Short Sleeve Basics Fashion Tee Work Breathable Streetwear | E33: 1548 | F33: 2.46 | G33: 2000 | H33: 4.7 | I33: открыть | J33: custom print t shirt heavyweight cotton
A34: футболка | B34: — | C34: своя печать | D34: Men's Custom T-shirt With Your Own Logo Text And Photo Printed On The Front And Back Tshirt Costume Graphic Tee Tops | E34: 578 | G34: 2000 | H34: 4.7 | I34: открыть | J34: custom print t shirt heavyweight cotton
A35: футболка | B35: — | C35: своя печать | D35: Customized T-Shirts Free Printing Logo Images Old Design Clothes 100% Cotton Cultural Shirts Men's and Women's Work Clothes | E35: 1975 | F35: 3.39 | G35: 2000 | H35: 4.8 | I35: открыть | J35: custom print t shirt heavyweight cotton
A36: кофта | B36: — | C36: своя печать | D36: Customized 60% Cotton Hoodie Men Fashion Long Sleeve Sweatshirts Women Personality Printed Streetwear Hoody Pullovers Sudaderas | E36: 1340 | G36: 2000 | H36: 4.6 | I36: открыть | J36: custom logo hoodie heavyweight
A37: кепка | B37: — | C37: своя печать | D37: Custom Logo Diy Baseball Cap Unisex Adjustable Men Women Sport Trucker Hat Solid Color Personalized Print Hip Hop Dad Caps | E37: 401 | F37: 1.09 | G37: 1000 | H37: 4.5 | I37: открыть | J37: ferrari f1 cap
A38: кепка | B38: — | C38: своя печать | D38: Multi Colors Foam Trucker Caps Custom Logo Sports Hip Hop Snapback Hats Men Women Breathable Baseball Cap Diy Personalised Logo | E38: 283 | G38: 1000 | H38: 4.8 | I38: открыть | J38: ferrari f1 cap
A39: кепка | B39: — | C39: своя печать | D39: Unisex Summer Cheaper Trucker Hat Custom Logo Personality Baseball Cap Breathable Mesh Casual Snapback Hat Visor | E39: 407 | G39: 1000 | H39: 4.6 | I39: открыть | J39: ferrari f1 cap
A40: кепка | B40: — | C40: своя печать | D40: Customize Men Caps Custom Baseball Cap Women Tennis Hats Print Or Embroidery Logo Text Casual Hats Black Cap Visors Hats | E40: 528 | G40: 1000 | H40: 4.7 | I40: открыть | J40: ferrari f1 cap
A41: кепка | B41: — | C41: своя печать | D41: Custom Baseball Caps Hat Custom Logo Men's Cap Hip Hop Snapback Adjustable Embroidery Print DIY Team Logo Designer Baseball Caps | E41: 308 | G41: 1000 | H41: 4.9 | I41: открыть | J41: mclaren f1 cap
...

Sheet Постеры — размеры
A1: Постеры: цена по размерам
A2: Лот 1005005851892159: 21 дизайн, холст без рамки, цена одинакова для всех дизайнов. Оценка 4.4, 112 заказов. «На сайт» — какие размеры предлагать (по умолчанию 4 ходовых).
A4: Размер | B4: Цена на Ali, ₽ | C4: Наша цена, ₽ | D4: Прибыль с шт., ₽ | E4: На сайт
A5: 13×18 см | B5: 289 | C5: =IF(B5="","",IF(B5<Параметры!$B$4,CEILING(B5*Параметры!$B$5,100)-10,IF(B5<=Параметры!$B$6,CEILING(B5*Параметры!$B$7,100)-10,CEILING(B5*Параметры!$B$8,100)-10))) -> 590 | D5: =IF(B5="","",ROUND(C5*(1-Параметры!$B$9-Параметры!$B$10-Параметры!$B$11)-B5,0)) -> 215
A6: 15×20 см | B6: 379 | C6: =IF(B6="","",IF(B6<Параметры!$B$4,CEILING(B6*Параметры!$B$5,100)-10,IF(B6<=Параметры!$B$6,CEILING(B6*Параметры!$B$7,100)-10,CEILING(B6*Параметры!$B$8,100)-10))) -> 790 | D6: =IF(B6="","",ROUND(C6*(1-Параметры!$B$9-Параметры!$B$10-Параметры!$B$11)-B6,0)) -> 296
A7: 20×25 см | B7: 472 | C7: =IF(B7="","",IF(B7<Параметры!$B$4,CEILING(B7*Параметры!$B$5,100)-10,IF(B7<=Параметры!$B$6,CEILING(B7*Параметры!$B$7,100)-10,CEILING(B7*Параметры!$B$8,100)-10))) -> 990 | D7: =IF(B7="","",ROUND(C7*(1-Параметры!$B$9-Параметры!$B$10-Параметры!$B$11)-B7,0)) -> 374
A8: 20×30 см | B8: 519 | C8: =IF(B8="","",IF(B8<Параметры!$B$4,CEILING(B8*Параметры!$B$5,100)-10,IF(B8<=Параметры!$B$6,CEILING(B8*Параметры!$B$7,100)-10,CEILING(B8*Параметры!$B$8,100)-10))) -> 1090 | D8: =IF(B8="","",ROUND(C8*(1-Параметры!$B$9-Параметры!$B$10-Параметры!$B$11)-B8,0)) -> 413 | E8: да
A9: 30×40 см | B9: 629 | C9: =IF(B9="","",IF(B9<Параметры!$B$4,CEILING(B9*Параметры!$B$5,100)-10,IF(B9<=Параметры!$B$6,CEILING(B9*Параметры!$B$7,100)-10,CEILING(B9*Параметры!$B$8,100)-10))) -> 1290 | D9: =IF(B9="","",ROUND(C9*(1-Параметры!$B$9-Параметры!$B$10-Параметры!$B$11)-B9,0)) -> 474 | E9: да
A10: 40×50 см | B10: 829 | C10: =IF(B10="","",IF(B10<Параметры!$B$4,CEILING(B10*Параметры!$B$5,100)-10,IF(B10<=Параметры!$B$6,CEILING(B10*Параметры!$B$7,100)-10,CEILING(B10*Параметры!$B$8,100)-10))) -> 1690 | D10: =IF(B10="","",ROUND(C10*(1-Параметры!$B$9-Параметры!$B$10-Параметры!$B$11)-B10,0)) -> 616
A11: 40×60 см | B11: 931 | C11: =IF(B11="","",IF(B11<Параметры!$B$4,CEILING(B11*Параметры!$B$5,100)-10,IF(B11<=Параметры!$B$6,CEILING(B11*Параметры!$B$7,100)-10,CEILING(B11*Параметры!$B$8,100)-10))) -> 1890 | D11: =IF(B11="","",ROUND(C11*(1-Параметры!$B$9-Параметры!$B$10-Параметры!$B$11)-B11,0)) -> 685 | E11: да
A12: 50×70 см | B12: 1052 | C12: =IF(B12="","",IF(B12<Параметры!$B$4,CEILING(B12*Параметры!$B$5,100)-10,IF(B12<=Параметры!$B$6,CEILING(B12*Параметры!$B$7,100)-10,CEILING(B12*Параметры!$B$8,100)-10))) -> 2190 | D12: =IF(B12="","",ROUND(C12*(1-Параметры!$B$9-Параметры!$B$10-Параметры!$B$11)-B12,0)) -> 820 | E12: да
A13: 60×80 см | B13: 1269 | C13: =IF(B13="","",IF(B13<Параметры!$B$4,CEILING(B13*Параметры!$B$5,100)-10,IF(B13<=Параметры!$B$6,CEILING(B13*Параметры!$B$7,100)-10,CEILING(B13*Параметры!$B$8,100)-10))) -> 2590 | D13: =IF(B13="","",ROUND(C13*(1-Параметры!$B$9-Параметры!$B$10-Параметры!$B$11)-B13,0)) -> 945
A14: 60×90 см | B14: 1372 | C14: =IF(B14="","",IF(B14<Параметры!$B$4,CEILING(B14*Параметры!$B$5,100)-10,IF(B14<=Параметры!$B$6,CEILING(B14*Параметры!$B$7,100)-10,CEILING(B14*Параметры!$B$8,100)-10))) -> 2790 | D14: =IF(B14="","",ROUND(C14*(1-Параметры!$B$9-Параметры!$B$10-Параметры!$B$11)-B14,0)) -> 1013
A16: Дизайны
A17: SKU-1 | B17: McLaren M23
A18: SKU-2 | B18: McLaren-Mercedes MP4-23
A19: SKU-3 | B19: McLaren MCL34
A20: SKU-4 | B20: Lotus 98T
A21: SKU-5 | B21: Red Bull Racing RB16
A22: SKU-6 | B22: Lotus 99T
A23: SKU-7 | B23: Jordan 191
A24: SKU-8 | B24: Mercedes AMG W10
A25: SKU-9 | B25: McLaren MP4/5B
A26: SKU-10 | B26: McLaren MP4/4
A27: SKU-11 | B27: McLaren MP4/6
A28: SKU-12 | B28: Brawn BGP001
... A37: SKU-21 | B37: Schumacher / Ferrari (японский стиль)

Sheet Варианты AliExpress
A1: Все варианты моделей из лотов (CSV из Chrome, 25.09.2026)
A2: «В ассортименте» — вариант взят на лист «Ассортимент». «Дубль» — такой же есть дешевле или с бо́льшим числом заказов. «Убрано» — версии, которые решили не брать.
A4: Лот | B4: Вариант на Ali | C4: Болид | D4: Пилот | E4: Ливрея / версия | F4: Год | G4: Масштаб | H4: Цена, ₽ | I4: Рейтинг | J4: Заказов | K4: Статус
A5: 1005010208916818 | B5: 1-VER-Japan | C5: Red Bull RB21 | D5: Ферстаппен #1 | E5: белая, ГП Японии | F5: 2025 | G5: 1:43 | H5: 789 | I5: 4.9 | J5: 1947 | K5: в ассортименте
A6: 1005010208916818 | B6: 22-TSU-Japan | C6: Red Bull RB21 | D6: Цунода #22 | E6: белая, ГП Японии | F6: 2025 | G6: 1:43 | H6: 789 | I6: 4.9 | J6: 1947 | K6: в ассортименте
A7: 1005010208916818 | B7: 22-TSU-Bahrain | C7: Red Bull RB21 | D7: Цунода #22 | E7: стандартная | F7: 2025 | G7: 1:43 | H7: 789 | I7: 4.9 | J7: 1947 | K7: в ассортименте
A8: 1005010208916818 | B8: 16-LEC | C8: Ferrari SF-25 | D8: Леклер #16 | E8: стандартная | F8: 2025 | G8: 1:43 | H8: 789 | I8: 4.9 | J8: 1947 | K8: в ассортименте
A9: 1005010208916818 | B9: 81-PIA-Australia | C9: McLaren MCL39 | D9: Пиастри #81 | E9: ГП Австралии | F9: 2025 | G9: 1:43 | H9: 789 | I9: 4.9 | J9: 1947 | K9: убрано: версия «Австралия»
A10: 1005010208916818 | B10: 63-RUS-Australia | C10: Mercedes W16 | D10: Рассел #63 | E10: ГП Австралии | F10: 2025 | G10: 1:43 | H10: 789 | I10: 4.9 | J10: 1947 | K10: убрано: версия «Австралия»
A11: 1005010208916818 | B11: 16-LEC-Miami | C11: Ferrari SF-25 | D11: Леклер #16 | E11: ГП Майами | F11: 2025 | G11: 1:43 | H11: 789 | I11: 4.9 | J11: 1947 | K11: в ассортименте
A12: 1005010208916818 | B12: 44-HAM-Miami | C12: Ferrari SF-25 | D12: Хэмилтон #44 | E12: ГП Майами | F12: 2025 | G12: 1:43 | H12: 789 | I12: 4.9 | J12: 1947 | K12: в ассортименте
A13: 1005010208916818 | B13: 4-NOR-Britain | C13: McLaren MCL39 | D13: Норрис #4 | E13: ГП Великобритании | F13: 2025 | G13: 1:43 | H13: 789 | I13: 4.9 | J13: 1947 | K13: убрано: ливрея «Великобритания»
A14: 1005010208916818 | B14: 81-PIA-Britain | C14: McLaren MCL39 | D14: Пиастри #81 | E14: ГП Великобритании | F14: 2025 | G14: 1:43 | H14: 789 | I14: 4.9 | J14: 1947 | K14: убрано: ливрея «Великобритания»
A15: 1005010208916818 | B15: 63-RUS-Britain | C15: Mercedes W16 | D15: Рассел #63 | E15: ГП Великобритании | F15: 2025 | G15: 1:43 | H15: 789 | I15: 4.9 | J15: 1947 | K15: убрано: ливрея «Великобритания»
A16: 1005010208755468 | B16: 2025 SF25-16 | C16: Ferrari SF-25 | D16: Леклер #16 | E16: стандартная | F16: 2025 | G16: 1:43 | H16: 879 | I16: 4.9 | J16: 791 | K16: дубль: берём лот …916818 за 789 ₽
... A61: 1005010633502926 | B61: 1-24 2024 SF24-55 | C61: Ferrari SF-24 | D61: Сайнс #55 | E61: стандартная | F61: 2024 | G61: 1:24 | H61: 2439 | I61: 4.9 | J61: 78 | K61: в ассортименте

Sheet Что уточнить
A1: Что осталось проверить
A3: Конструкторы CaDA 1:24 (2 лота) | B3: Цена нужного варианта, официальный магазин CaDA, число деталей и возраст на коробке. В CSV из Chrome этих лотов нет, цены — из поиска aliexpress.com: там была только цена для новых покупателей, в таблице — зачёркнутая как верхняя оценка. Реальная может быть до двух раз ниже.
A4: Реплики 1:8 (7 машин, 5 лотов) | B4: Цена нужного варианта и вариант «с коробкой»; фото коробки в отзывах: без логотипа LEGO, печать нормального качества. Жёлтые цены — верхняя оценка.
A5: Доставка | B5: Цены в таблице — за товар. Если доставка в РФ платная, прибавить её к цене на Ali.
A6: Новинки 2026 (1:43) | B6: Оценок нет, 31–45 заказов. Сначала заказать по одной для проверки качества.
A7: Мерч в стиле командной формы | B7: Цена нужного размера (жёлтые — верхняя оценка), фото из отзывов: качество печати и вышивки. Кепки и худи Ferrari, Red Bull, Mercedes, McLaren поискать на aliexpress.ru — на aliexpress.com их почти нет.
A8: Мерч — размеры | B8: У каждого продавца одежды взять таблицу размеров в сантиметрах: азиатская сетка обычно на 1–2 размера меньше.
A9: Постеры | B9: Оценка лота 4.4 — ниже остальных; посмотреть фото печати в отзывах.

Sheet Параметры
A1: Параметры расчёта
A2: Синие ячейки можно менять — цены и прибыль на листах «Ассортимент» и «Постеры — размеры» пересчитаются.
A4: Порог 1: закупка дешевле, ₽ | B4: 1500 | C4: Правило наценки из f1-shop/01-business-model.md
A5: Наценка до порога 1, × | B5: 2 | C5: Дешёвые позиции: ×2
A6: Порог 2: закупка до, ₽ | B6: 7000
A7: Наценка между порогами, × | B7: 1.6 | C7: Средние позиции: ×1,6
A8: Наценка дороже порога 2, × | B8: 1.35 | C8: Дорогие позиции: ×1,35
A9: Эквайринг, доля | B9: 0.035 | C9: ЮKassa, карта; по СБП меньше (f1-shop/03-payments.md)
A10: Налог УСН «Доходы», доля | B10: 0.06 | C10: ИП на УСН 6 %
A11: Резерв на возвраты, доля | B11: 0.05 | C11: f1-shop/01-business-model.md
A12: Лимит цены для 1:24, ₽ | B12: 2800 | C12: Правило владельца магазина: 1:24 берём до 2 800 ₽
A13: Курс доллара, ₽ | B13: 84.2 | C13: ЦБ РФ на 20.09.2026 — для лотов с aliexpress.com (конструкторы, мерч)
A14: Резерв на возвраты, одежда, доля | B14: 0.1 | C14: По одежде возвратов больше — размер (f1-shop/10-content.md)
